2024-05-11 21:30:26,087 ERROR: Exception on / [GET] [in C:\Users\gulto\project\GroupProject\venv\Lib\site-packages\flask\app.py:838]
Traceback (most recent call last):
  File "C:\Users\gulto\project\GroupProject\venv\Lib\site-packages\sqlalchemy\engine\base.py", line 1967, in _exec_single_context
    self.dialect.do_execute(
  File "C:\Users\gulto\project\GroupProject\venv\Lib\site-packages\sqlalchemy\engine\default.py", line 924, in do_execute
    cursor.execute(statement, parameters)
sqlite3.OperationalError: no such column: user.about_me

The above exception was the direct cause of the following exception:

Traceback (most recent call last):
  File "C:\Users\gulto\project\GroupProject\venv\Lib\site-packages\flask\app.py", line 1473, in wsgi_app
    response = self.full_dispatch_request()
               ^^^^^^^^^^^^^^^^^^^^^^^^^^^^
  File "C:\Users\gulto\project\GroupProject\venv\Lib\site-packages\flask\app.py", line 882, in full_dispatch_request
    rv = self.handle_user_exception(e)
         ^^^^^^^^^^^^^^^^^^^^^^^^^^^^^
  File "C:\Users\gulto\project\GroupProject\venv\Lib\site-packages\flask\app.py", line 878, in full_dispatch_request
    rv = self.preprocess_request()
         ^^^^^^^^^^^^^^^^^^^^^^^^^
  File "C:\Users\gulto\project\GroupProject\venv\Lib\site-packages\flask\app.py", line 1253, in preprocess_request
    rv = self.ensure_sync(before_func)()
         ^^^^^^^^^^^^^^^^^^^^^^^^^^^^^^^
  File "C:\Users\gulto\project\GroupProject\app\routes.py", line 162, in before_request
    if current_user.is_authenticated:
       ^^^^^^^^^^^^^^^^^^^^^^^^^^^^^
  File "C:\Users\gulto\project\GroupProject\venv\Lib\site-packages\werkzeug\local.py", line 318, in __get__
    obj = instance._get_current_object()
          ^^^^^^^^^^^^^^^^^^^^^^^^^^^^^^
  File "C:\Users\gulto\project\GroupProject\venv\Lib\site-packages\werkzeug\local.py", line 526, in _get_current_object
    return get_name(local())
                    ^^^^^^^
  File "C:\Users\gulto\project\GroupProject\venv\Lib\site-packages\flask_login\utils.py", line 25, in <lambda>
    current_user = LocalProxy(lambda: _get_user())
                                      ^^^^^^^^^^^
  File "C:\Users\gulto\project\GroupProject\venv\Lib\site-packages\flask_login\utils.py", line 370, in _get_user
    current_app.login_manager._load_user()
  File "C:\Users\gulto\project\GroupProject\venv\Lib\site-packages\flask_login\login_manager.py", line 364, in _load_user
    user = self._user_callback(user_id)
           ^^^^^^^^^^^^^^^^^^^^^^^^^^^^
  File "C:\Users\gulto\project\GroupProject\app\models.py", line 44, in load_user
    return db.session.get(User, int(id))
           ^^^^^^^^^^^^^^^^^^^^^^^^^^^^^
  File "C:\Users\gulto\project\GroupProject\venv\Lib\site-packages\sqlalchemy\orm\scoping.py", line 1060, in get
    return self._proxied.get(
           ^^^^^^^^^^^^^^^^^^
  File "C:\Users\gulto\project\GroupProject\venv\Lib\site-packages\sqlalchemy\orm\session.py", line 3682, in get
    return self._get_impl(
           ^^^^^^^^^^^^^^^
  File "C:\Users\gulto\project\GroupProject\venv\Lib\site-packages\sqlalchemy\orm\session.py", line 3862, in _get_impl
    return db_load_fn(
           ^^^^^^^^^^^
  File "C:\Users\gulto\project\GroupProject\venv\Lib\site-packages\sqlalchemy\orm\loading.py", line 694, in load_on_pk_identity
    session.execute(
  File "C:\Users\gulto\project\GroupProject\venv\Lib\site-packages\sqlalchemy\orm\session.py", line 2351, in execute
    return self._execute_internal(
           ^^^^^^^^^^^^^^^^^^^^^^^
  File "C:\Users\gulto\project\GroupProject\venv\Lib\site-packages\sqlalchemy\orm\session.py", line 2236, in _execute_internal
    result: Result[Any] = compile_state_cls.orm_execute_statement(
                          ^^^^^^^^^^^^^^^^^^^^^^^^^^^^^^^^^^^^^^^^
  File "C:\Users\gulto\project\GroupProject\venv\Lib\site-packages\sqlalchemy\orm\context.py", line 293, in orm_execute_statement
    result = conn.execute(
             ^^^^^^^^^^^^^
  File "C:\Users\gulto\project\GroupProject\venv\Lib\site-packages\sqlalchemy\engine\base.py", line 1418, in execute
    return meth(
           ^^^^^
  File "C:\Users\gulto\project\GroupProject\venv\Lib\site-packages\sqlalchemy\sql\elements.py", line 515, in _execute_on_connection
    return connection._execute_clauseelement(
           ^^^^^^^^^^^^^^^^^^^^^^^^^^^^^^^^^^
  File "C:\Users\gulto\project\GroupProject\venv\Lib\site-packages\sqlalchemy\engine\base.py", line 1640, in _execute_clauseelement
    ret = self._execute_context(
          ^^^^^^^^^^^^^^^^^^^^^^
  File "C:\Users\gulto\project\GroupProject\venv\Lib\site-packages\sqlalchemy\engine\base.py", line 1846, in _execute_context
    return self._exec_single_context(
           ^^^^^^^^^^^^^^^^^^^^^^^^^^
  File "C:\Users\gulto\project\GroupProject\venv\Lib\site-packages\sqlalchemy\engine\base.py", line 1986, in _exec_single_context
    self._handle_dbapi_exception(
  File "C:\Users\gulto\project\GroupProject\venv\Lib\site-packages\sqlalchemy\engine\base.py", line 2353, in _handle_dbapi_exception
    raise sqlalchemy_exception.with_traceback(exc_info[2]) from e
  File "C:\Users\gulto\project\GroupProject\venv\Lib\site-packages\sqlalchemy\engine\base.py", line 1967, in _exec_single_context
    self.dialect.do_execute(
  File "C:\Users\gulto\project\GroupProject\venv\Lib\site-packages\sqlalchemy\engine\default.py", line 924, in do_execute
    cursor.execute(statement, parameters)
sqlalchemy.exc.OperationalError: (sqlite3.OperationalError) no such column: user.about_me
[SQL: SELECT user.id AS user_id, user.username AS user_username, user.email AS user_email, user.password_hash AS user_password_hash, user.about_me AS user_about_me, user.last_seen AS user_last_seen, user.points AS user_points 
FROM user 
WHERE user.id = ?]
[parameters: (6,)]
(Background on this error at: https://sqlalche.me/e/20/e3q8)
2024-05-11 21:30:49,490 INFO: ValueCheck startup [in C:\Users\gulto\project\GroupProject\app\__init__.py:52]
2024-05-11 21:30:54,132 INFO: ValueCheck startup [in C:\Users\gulto\project\GroupProject\app\__init__.py:52]
2024-05-11 21:30:57,848 INFO: ValueCheck startup [in C:\Users\gulto\project\GroupProject\app\__init__.py:52]
2024-05-11 21:31:01,831 INFO: ValueCheck startup [in C:\Users\gulto\project\GroupProject\app\__init__.py:52]
2024-05-11 21:33:46,601 INFO: ValueCheck startup [in C:\Users\gulto\project\GroupProject\app\__init__.py:52]
2024-05-11 21:33:52,058 INFO: ValueCheck startup [in C:\Users\gulto\project\GroupProject\app\__init__.py:52]
2024-05-11 21:35:47,608 INFO: ValueCheck startup [in C:\Users\gulto\project\GroupProject\app\__init__.py:52]
2024-05-12 01:16:04,100 INFO: ValueCheck startup [in C:\Users\gulto\project\GroupProject\app\__init__.py:52]
2024-05-12 01:23:14,180 INFO: ValueCheck startup [in C:\Users\gulto\project\GroupProject\app\__init__.py:52]
2024-05-12 01:23:16,296 INFO: ValueCheck startup [in C:\Users\gulto\project\GroupProject\app\__init__.py:52]
2024-05-12 01:23:18,629 ERROR: Exception on /leaderboard [GET] [in C:\Users\gulto\project\GroupProject\venv\Lib\site-packages\flask\app.py:838]
Traceback (most recent call last):
  File "C:\Users\gulto\project\GroupProject\venv\Lib\site-packages\flask\app.py", line 1473, in wsgi_app
    response = self.full_dispatch_request()
               ^^^^^^^^^^^^^^^^^^^^^^^^^^^^
  File "C:\Users\gulto\project\GroupProject\venv\Lib\site-packages\flask\app.py", line 882, in full_dispatch_request
    rv = self.handle_user_exception(e)
         ^^^^^^^^^^^^^^^^^^^^^^^^^^^^^
  File "C:\Users\gulto\project\GroupProject\venv\Lib\site-packages\flask\app.py", line 880, in full_dispatch_request
    rv = self.dispatch_request()
         ^^^^^^^^^^^^^^^^^^^^^^^
  File "C:\Users\gulto\project\GroupProject\venv\Lib\site-packages\flask\app.py", line 865, in dispatch_request
    return self.ensure_sync(self.view_functions[rule.endpoint])(**view_args)  # type: ignore[no-any-return]
           ^^^^^^^^^^^^^^^^^^^^^^^^^^^^^^^^^^^^^^^^^^^^^^^^^^^^^^^^^^^^^^^^^
  File "C:\Users\gulto\project\GroupProject\app\routes.py", line 101, in leaderboard
    return render_template('leaderboard_1.html', title='Leaderboard')
           ^^^^^^^^^^^^^^^^^^^^^^^^^^^^^^^^^^^^^^^^^^^^^^^^^^^^^^^^^^
  File "C:\Users\gulto\project\GroupProject\venv\Lib\site-packages\flask\templating.py", line 149, in render_template
    template = app.jinja_env.get_or_select_template(template_name_or_list)
               ^^^^^^^^^^^^^^^^^^^^^^^^^^^^^^^^^^^^^^^^^^^^^^^^^^^^^^^^^^^
  File "C:\Users\gulto\project\GroupProject\venv\Lib\site-packages\jinja2\environment.py", line 1084, in get_or_select_template
    return self.get_template(template_name_or_list, parent, globals)
           ^^^^^^^^^^^^^^^^^^^^^^^^^^^^^^^^^^^^^^^^^^^^^^^^^^^^^^^^^
  File "C:\Users\gulto\project\GroupProject\venv\Lib\site-packages\jinja2\environment.py", line 1013, in get_template
    return self._load_template(name, globals)
           ^^^^^^^^^^^^^^^^^^^^^^^^^^^^^^^^^^
  File "C:\Users\gulto\project\GroupProject\venv\Lib\site-packages\jinja2\environment.py", line 972, in _load_template
    template = self.loader.load(self, name, self.make_globals(globals))
               ^^^^^^^^^^^^^^^^^^^^^^^^^^^^^^^^^^^^^^^^^^^^^^^^^^^^^^^^
  File "C:\Users\gulto\project\GroupProject\venv\Lib\site-packages\jinja2\loaders.py", line 138, in load
    code = environment.compile(source, name, filename)
           ^^^^^^^^^^^^^^^^^^^^^^^^^^^^^^^^^^^^^^^^^^^
  File "C:\Users\gulto\project\GroupProject\venv\Lib\site-packages\jinja2\environment.py", line 768, in compile
    self.handle_exception(source=source_hint)
  File "C:\Users\gulto\project\GroupProject\venv\Lib\site-packages\jinja2\environment.py", line 939, in handle_exception
    raise rewrite_traceback_stack(source=source)
  File "C:\Users\gulto\project\GroupProject\app\templates\leaderboard_1.html", line 7, in template
    {% block content %}
jinja2.exceptions.TemplateAssertionError: block 'content' defined twice
2024-05-12 01:23:45,210 INFO: ValueCheck startup [in C:\Users\gulto\project\GroupProject\app\__init__.py:52]
