2024-05-12 03:00:30,774 INFO: ValueCheck startup [in C:\Users\gulto\project\GroupProject\app\__init__.py:52]
2024-05-12 03:00:35,353 INFO: ValueCheck startup [in C:\Users\gulto\project\GroupProject\app\__init__.py:52]
2024-05-12 03:00:43,693 INFO: ValueCheck startup [in C:\Users\gulto\project\GroupProject\app\__init__.py:52]
2024-05-12 03:00:47,096 INFO: ValueCheck startup [in C:\Users\gulto\project\GroupProject\app\__init__.py:52]
2024-05-12 03:02:04,748 INFO: ValueCheck startup [in C:\Users\gulto\project\GroupProject\app\__init__.py:52]
2024-05-12 03:02:07,691 ERROR: Exception on /update_user [POST] [in C:\Users\gulto\project\GroupProject\venv\Lib\site-packages\flask\app.py:838]
Traceback (most recent call last):
  File "C:\Users\gulto\project\GroupProject\venv\Lib\site-packages\sqlalchemy\engine\base.py", line 1967, in _exec_single_context
    self.dialect.do_execute(
  File "C:\Users\gulto\project\GroupProject\venv\Lib\site-packages\sqlalchemy\engine\default.py", line 924, in do_execute
    cursor.execute(statement, parameters)
sqlite3.IntegrityError: UNIQUE constraint failed: user.username

The above exception was the direct cause of the following exception:

Traceback (most recent call last):
  File "C:\Users\gulto\project\GroupProject\venv\Lib\site-packages\flask\app.py", line 1473, in wsgi_app
    response = self.full_dispatch_request()
               ^^^^^^^^^^^^^^^^^^^^^^^^^^^^
  File "C:\Users\gulto\project\GroupProject\venv\Lib\site-packages\flask\app.py", line 882, in full_dispatch_request
    rv = self.handle_user_exception(e)
         ^^^^^^^^^^^^^^^^^^^^^^^^^^^^^
  File "C:\Users\gulto\project\GroupProject\venv\Lib\site-packages\flask\app.py", line 880, in full_dispatch_request
    rv = self.dispatch_request()
         ^^^^^^^^^^^^^^^^^^^^^^^
  File "C:\Users\gulto\project\GroupProject\venv\Lib\site-packages\flask\app.py", line 865, in dispatch_request
    return self.ensure_sync(self.view_functions[rule.endpoint])(**view_args)  # type: ignore[no-any-return]
           ^^^^^^^^^^^^^^^^^^^^^^^^^^^^^^^^^^^^^^^^^^^^^^^^^^^^^^^^^^^^^^^^^
  File "C:\Users\gulto\project\GroupProject\venv\Lib\site-packages\flask_login\utils.py", line 290, in decorated_view
    return current_app.ensure_sync(func)(*args, **kwargs)
           ^^^^^^^^^^^^^^^^^^^^^^^^^^^^^^^^^^^^^^^^^^^^^^
  File "C:\Users\gulto\project\GroupProject\app\routes.py", line 128, in edit_profile
    db.session.commit()
  File "C:\Users\gulto\project\GroupProject\venv\Lib\site-packages\sqlalchemy\orm\scoping.py", line 597, in commit
    return self._proxied.commit()
           ^^^^^^^^^^^^^^^^^^^^^^
  File "C:\Users\gulto\project\GroupProject\venv\Lib\site-packages\sqlalchemy\orm\session.py", line 2017, in commit
    trans.commit(_to_root=True)
  File "<string>", line 2, in commit
  File "C:\Users\gulto\project\GroupProject\venv\Lib\site-packages\sqlalchemy\orm\state_changes.py", line 139, in _go
    ret_value = fn(self, *arg, **kw)
                ^^^^^^^^^^^^^^^^^^^^
  File "C:\Users\gulto\project\GroupProject\venv\Lib\site-packages\sqlalchemy\orm\session.py", line 1302, in commit
    self._prepare_impl()
  File "<string>", line 2, in _prepare_impl
  File "C:\Users\gulto\project\GroupProject\venv\Lib\site-packages\sqlalchemy\orm\state_changes.py", line 139, in _go
    ret_value = fn(self, *arg, **kw)
                ^^^^^^^^^^^^^^^^^^^^
  File "C:\Users\gulto\project\GroupProject\venv\Lib\site-packages\sqlalchemy\orm\session.py", line 1277, in _prepare_impl
    self.session.flush()
  File "C:\Users\gulto\project\GroupProject\venv\Lib\site-packages\sqlalchemy\orm\session.py", line 4341, in flush
    self._flush(objects)
  File "C:\Users\gulto\project\GroupProject\venv\Lib\site-packages\sqlalchemy\orm\session.py", line 4476, in _flush
    with util.safe_reraise():
  File "C:\Users\gulto\project\GroupProject\venv\Lib\site-packages\sqlalchemy\util\langhelpers.py", line 146, in __exit__
    raise exc_value.with_traceback(exc_tb)
  File "C:\Users\gulto\project\GroupProject\venv\Lib\site-packages\sqlalchemy\orm\session.py", line 4437, in _flush
    flush_context.execute()
  File "C:\Users\gulto\project\GroupProject\venv\Lib\site-packages\sqlalchemy\orm\unitofwork.py", line 466, in execute
    rec.execute(self)
  File "C:\Users\gulto\project\GroupProject\venv\Lib\site-packages\sqlalchemy\orm\unitofwork.py", line 642, in execute
    util.preloaded.orm_persistence.save_obj(
  File "C:\Users\gulto\project\GroupProject\venv\Lib\site-packages\sqlalchemy\orm\persistence.py", line 85, in save_obj
    _emit_update_statements(
  File "C:\Users\gulto\project\GroupProject\venv\Lib\site-packages\sqlalchemy\orm\persistence.py", line 912, in _emit_update_statements
    c = connection.execute(
        ^^^^^^^^^^^^^^^^^^^
  File "C:\Users\gulto\project\GroupProject\venv\Lib\site-packages\sqlalchemy\engine\base.py", line 1418, in execute
    return meth(
           ^^^^^
  File "C:\Users\gulto\project\GroupProject\venv\Lib\site-packages\sqlalchemy\sql\elements.py", line 515, in _execute_on_connection
    return connection._execute_clauseelement(
           ^^^^^^^^^^^^^^^^^^^^^^^^^^^^^^^^^^
  File "C:\Users\gulto\project\GroupProject\venv\Lib\site-packages\sqlalchemy\engine\base.py", line 1640, in _execute_clauseelement
    ret = self._execute_context(
          ^^^^^^^^^^^^^^^^^^^^^^
  File "C:\Users\gulto\project\GroupProject\venv\Lib\site-packages\sqlalchemy\engine\base.py", line 1846, in _execute_context
    return self._exec_single_context(
           ^^^^^^^^^^^^^^^^^^^^^^^^^^
  File "C:\Users\gulto\project\GroupProject\venv\Lib\site-packages\sqlalchemy\engine\base.py", line 1986, in _exec_single_context
    self._handle_dbapi_exception(
  File "C:\Users\gulto\project\GroupProject\venv\Lib\site-packages\sqlalchemy\engine\base.py", line 2353, in _handle_dbapi_exception
    raise sqlalchemy_exception.with_traceback(exc_info[2]) from e
  File "C:\Users\gulto\project\GroupProject\venv\Lib\site-packages\sqlalchemy\engine\base.py", line 1967, in _exec_single_context
    self.dialect.do_execute(
  File "C:\Users\gulto\project\GroupProject\venv\Lib\site-packages\sqlalchemy\engine\default.py", line 924, in do_execute
    cursor.execute(statement, parameters)
sqlalchemy.exc.IntegrityError: (sqlite3.IntegrityError) UNIQUE constraint failed: user.username
[SQL: UPDATE user SET username=?, email=?, about_me=? WHERE user.id = ?]
[parameters: ('khaizy', 'jfoahfaon@gmail.com', 'hfqnaogf', 2)]
(Background on this error at: https://sqlalche.me/e/20/gkpj)
2024-05-12 17:34:24,198 INFO: ValueCheck startup [in C:\Users\gulto\project\GroupProject\app\__init__.py:52]
2024-05-12 15:41:09,959 ERROR: Exception on /index [GET] [in /Library/Frameworks/Python.framework/Versions/3.12/lib/python3.12/site-packages/flask/app.py:838]
Traceback (most recent call last):
  File "/Library/Frameworks/Python.framework/Versions/3.12/lib/python3.12/site-packages/flask/app.py", line 1473, in wsgi_app
    response = self.full_dispatch_request()
               ^^^^^^^^^^^^^^^^^^^^^^^^^^^^
  File "/Library/Frameworks/Python.framework/Versions/3.12/lib/python3.12/site-packages/flask/app.py", line 882, in full_dispatch_request
    rv = self.handle_user_exception(e)
         ^^^^^^^^^^^^^^^^^^^^^^^^^^^^^
  File "/Library/Frameworks/Python.framework/Versions/3.12/lib/python3.12/site-packages/flask/app.py", line 880, in full_dispatch_request
    rv = self.dispatch_request()
         ^^^^^^^^^^^^^^^^^^^^^^^
  File "/Library/Frameworks/Python.framework/Versions/3.12/lib/python3.12/site-packages/flask/app.py", line 865, in dispatch_request
    return self.ensure_sync(self.view_functions[rule.endpoint])(**view_args)  # type: ignore[no-any-return]
           ^^^^^^^^^^^^^^^^^^^^^^^^^^^^^^^^^^^^^^^^^^^^^^^^^^^^^^^^^^^^^^^^^
  File "/Library/Frameworks/Python.framework/Versions/3.12/lib/python3.12/site-packages/flask_login/utils.py", line 290, in decorated_view
    return current_app.ensure_sync(func)(*args, **kwargs)
           ^^^^^^^^^^^^^^^^^^^^^^^^^^^^^^^^^^^^^^^^^^^^^^
  File "/Users/indragultom/GroupProject/app/routes.py", line 44, in search
    return redirect(url_for('index'))
                    ^^^^^^^^^^^^^^^^
  File "/Library/Frameworks/Python.framework/Versions/3.12/lib/python3.12/site-packages/flask/helpers.py", line 220, in url_for
    return current_app.url_for(
           ^^^^^^^^^^^^^^^^^^^^
  File "/Library/Frameworks/Python.framework/Versions/3.12/lib/python3.12/site-packages/flask/app.py", line 1084, in url_for
    return self.handle_url_build_error(error, endpoint, values)
           ^^^^^^^^^^^^^^^^^^^^^^^^^^^^^^^^^^^^^^^^^^^^^^^^^^^^
  File "/Library/Frameworks/Python.framework/Versions/3.12/lib/python3.12/site-packages/flask/app.py", line 1073, in url_for
    rv = url_adapter.build(  # type: ignore[union-attr]
         ^^^^^^^^^^^^^^^^^^^^^^^^^^^^^^^^^^^^^^^^^^^^^^
  File "/Library/Frameworks/Python.framework/Versions/3.12/lib/python3.12/site-packages/werkzeug/routing/map.py", line 926, in build
    raise BuildError(endpoint, values, method, self)
werkzeug.routing.exceptions.BuildError: Could not build url for endpoint 'index'. Did you mean 'login' instead?
2024-05-12 15:49:36,001 INFO: ValueCheck startup [in /Users/indragultom/GroupProject/app/__init__.py:52]
2024-05-12 15:49:46,596 INFO: ValueCheck startup [in /Users/indragultom/GroupProject/app/__init__.py:52]
2024-05-12 15:50:35,012 INFO: ValueCheck startup [in /Users/indragultom/GroupProject/app/__init__.py:52]
2024-05-12 15:52:02,441 INFO: ValueCheck startup [in /Users/indragultom/GroupProject/app/__init__.py:52]
2024-05-12 17:36:08,621 INFO: ValueCheck startup [in C:\Users\gulto\project\GroupProject\app\__init__.py:52]
2024-05-12 17:36:11,764 INFO: ValueCheck startup [in C:\Users\gulto\project\GroupProject\app\__init__.py:52]
2024-05-12 17:36:17,510 INFO: ValueCheck startup [in C:\Users\gulto\project\GroupProject\app\__init__.py:52]
2024-05-12 17:36:21,581 INFO: ValueCheck startup [in C:\Users\gulto\project\GroupProject\app\__init__.py:52]
