2024-05-15 20:07:36,719 ERROR: Exception on /update_user [POST] [in /opt/anaconda3/lib/python3.11/site-packages/flask/app.py:1744]
Traceback (most recent call last):
  File "/opt/anaconda3/lib/python3.11/site-packages/sqlalchemy/engine/base.py", line 1969, in _exec_single_context
    self.dialect.do_execute(
  File "/opt/anaconda3/lib/python3.11/site-packages/sqlalchemy/engine/default.py", line 922, in do_execute
    cursor.execute(statement, parameters)
sqlite3.IntegrityError: UNIQUE constraint failed: user.email

The above exception was the direct cause of the following exception:

Traceback (most recent call last):
  File "/opt/anaconda3/lib/python3.11/site-packages/flask/app.py", line 2529, in wsgi_app
    response = self.full_dispatch_request()
               ^^^^^^^^^^^^^^^^^^^^^^^^^^^^
  File "/opt/anaconda3/lib/python3.11/site-packages/flask/app.py", line 1825, in full_dispatch_request
    rv = self.handle_user_exception(e)
         ^^^^^^^^^^^^^^^^^^^^^^^^^^^^^
  File "/opt/anaconda3/lib/python3.11/site-packages/flask/app.py", line 1823, in full_dispatch_request
    rv = self.dispatch_request()
         ^^^^^^^^^^^^^^^^^^^^^^^
  File "/opt/anaconda3/lib/python3.11/site-packages/flask/app.py", line 1799, in dispatch_request
    return self.ensure_sync(self.view_functions[rule.endpoint])(**view_args)
           ^^^^^^^^^^^^^^^^^^^^^^^^^^^^^^^^^^^^^^^^^^^^^^^^^^^^^^^^^^^^^^^^^
  File "/opt/anaconda3/lib/python3.11/site-packages/flask_login/utils.py", line 290, in decorated_view
    return current_app.ensure_sync(func)(*args, **kwargs)
           ^^^^^^^^^^^^^^^^^^^^^^^^^^^^^^^^^^^^^^^^^^^^^^
  File "/Users/jessicaharcourt-cooke/Desktop/GroupProject/GroupProject/app/routes.py", line 164, in edit_profile
    db.session.commit()
  File "/opt/anaconda3/lib/python3.11/site-packages/sqlalchemy/orm/scoping.py", line 598, in commit
    return self._proxied.commit()
           ^^^^^^^^^^^^^^^^^^^^^^
  File "/opt/anaconda3/lib/python3.11/site-packages/sqlalchemy/orm/session.py", line 1969, in commit
    trans.commit(_to_root=True)
  File "<string>", line 2, in commit
  File "/opt/anaconda3/lib/python3.11/site-packages/sqlalchemy/orm/state_changes.py", line 139, in _go
    ret_value = fn(self, *arg, **kw)
                ^^^^^^^^^^^^^^^^^^^^
  File "/opt/anaconda3/lib/python3.11/site-packages/sqlalchemy/orm/session.py", line 1256, in commit
    self._prepare_impl()
  File "<string>", line 2, in _prepare_impl
  File "/opt/anaconda3/lib/python3.11/site-packages/sqlalchemy/orm/state_changes.py", line 139, in _go
    ret_value = fn(self, *arg, **kw)
                ^^^^^^^^^^^^^^^^^^^^
  File "/opt/anaconda3/lib/python3.11/site-packages/sqlalchemy/orm/session.py", line 1231, in _prepare_impl
    self.session.flush()
  File "/opt/anaconda3/lib/python3.11/site-packages/sqlalchemy/orm/session.py", line 4312, in flush
    self._flush(objects)
  File "/opt/anaconda3/lib/python3.11/site-packages/sqlalchemy/orm/session.py", line 4447, in _flush
    with util.safe_reraise():
  File "/opt/anaconda3/lib/python3.11/site-packages/sqlalchemy/util/langhelpers.py", line 146, in __exit__
    raise exc_value.with_traceback(exc_tb)
  File "/opt/anaconda3/lib/python3.11/site-packages/sqlalchemy/orm/session.py", line 4408, in _flush
    flush_context.execute()
  File "/opt/anaconda3/lib/python3.11/site-packages/sqlalchemy/orm/unitofwork.py", line 466, in execute
    rec.execute(self)
  File "/opt/anaconda3/lib/python3.11/site-packages/sqlalchemy/orm/unitofwork.py", line 642, in execute
    util.preloaded.orm_persistence.save_obj(
  File "/opt/anaconda3/lib/python3.11/site-packages/sqlalchemy/orm/persistence.py", line 85, in save_obj
    _emit_update_statements(
  File "/opt/anaconda3/lib/python3.11/site-packages/sqlalchemy/orm/persistence.py", line 910, in _emit_update_statements
    c = connection.execute(
        ^^^^^^^^^^^^^^^^^^^
  File "/opt/anaconda3/lib/python3.11/site-packages/sqlalchemy/engine/base.py", line 1416, in execute
    return meth(
           ^^^^^
  File "/opt/anaconda3/lib/python3.11/site-packages/sqlalchemy/sql/elements.py", line 517, in _execute_on_connection
    return connection._execute_clauseelement(
           ^^^^^^^^^^^^^^^^^^^^^^^^^^^^^^^^^^
  File "/opt/anaconda3/lib/python3.11/site-packages/sqlalchemy/engine/base.py", line 1639, in _execute_clauseelement
    ret = self._execute_context(
          ^^^^^^^^^^^^^^^^^^^^^^
  File "/opt/anaconda3/lib/python3.11/site-packages/sqlalchemy/engine/base.py", line 1848, in _execute_context
    return self._exec_single_context(
           ^^^^^^^^^^^^^^^^^^^^^^^^^^
  File "/opt/anaconda3/lib/python3.11/site-packages/sqlalchemy/engine/base.py", line 1988, in _exec_single_context
    self._handle_dbapi_exception(
  File "/opt/anaconda3/lib/python3.11/site-packages/sqlalchemy/engine/base.py", line 2344, in _handle_dbapi_exception
    raise sqlalchemy_exception.with_traceback(exc_info[2]) from e
  File "/opt/anaconda3/lib/python3.11/site-packages/sqlalchemy/engine/base.py", line 1969, in _exec_single_context
    self.dialect.do_execute(
  File "/opt/anaconda3/lib/python3.11/site-packages/sqlalchemy/engine/default.py", line 922, in do_execute
    cursor.execute(statement, parameters)
sqlalchemy.exc.IntegrityError: (sqlite3.IntegrityError) UNIQUE constraint failed: user.email
[SQL: UPDATE user SET username=?, email=?, about_me=?, img=?, mimetype=? WHERE user.id = ?]
[parameters: ('meowmeowmeow', 'meow@gmail.com', 'Live Love Laugh ', '/9j/4AAQSkZJRgABAgEASABIAAD/4TLJRXhpZgAATU0AKgAAAAgADAEPAAIAAAAGAAAAngEQAAIAAAAPAAAApAESAAMAAAABAAYAAAEaAAUAAAABAAAAtAEbAAUAAAABAAAAvAEoAAMAAAABAAIAA ... (5095714 characters truncated) ... FuzoAcYI6V83+KoRrXxFlt9RZpI1bYFzgYFZydp2A9ovZrH4n+AZ9SeEwfYl3DHIJr5e8P7odWTTrw/IGZoynJGK+s9Vhi8OeAZ7DSVEULLgjqTx618u+FIkTVvthG6TeR83IAxWsIpXKktmf/9k=', 'image/jpeg', 20)]
(Background on this error at: https://sqlalche.me/e/20/gkpj)
2024-05-15 20:16:05,494 INFO: ValueCheck startup [in /Users/jessicaharcourt-cooke/Desktop/GroupProject/GroupProject/app/__init__.py:50]
2024-05-15 20:18:36,691 INFO: ValueCheck startup [in /Users/jessicaharcourt-cooke/Desktop/GroupProject/GroupProject/app/__init__.py:50]
2024-05-15 20:20:14,470 INFO: ValueCheck startup [in /Users/jessicaharcourt-cooke/Desktop/GroupProject/GroupProject/app/__init__.py:50]
2024-05-15 20:25:13,570 INFO: ValueCheck startup [in /Users/jessicaharcourt-cooke/Desktop/GroupProject/GroupProject/app/__init__.py:50]
2024-05-15 20:28:18,913 INFO: ValueCheck startup [in /Users/jessicaharcourt-cooke/Desktop/GroupProject/GroupProject/app/__init__.py:50]
2024-05-15 20:30:02,360 INFO: ValueCheck startup [in /Users/jessicaharcourt-cooke/Desktop/GroupProject/GroupProject/app/__init__.py:50]
2024-05-15 21:17:21,793 INFO: ValueCheck startup [in /Users/jessicaharcourt-cooke/Desktop/GroupProject/GroupProject/app/__init__.py:50]
2024-05-15 21:21:10,481 INFO: ValueCheck startup [in /Users/jessicaharcourt-cooke/Desktop/GroupProject/GroupProject/app/__init__.py:50]
